/**
 * 认证错误处理测试
 */

// Jest globals are available globally, no need to import

// Mock next/navigation
jest.mock('next/navigation', () => ({
  useRouter: jest.fn(() => ({
    push: jest.fn(),
    replace: jest.fn(),
    refresh: jest.fn(),
  })),
  useSearchParams: jest.fn(() => new URLSearchParams()),
}))

// Mock next-intl
jest.mock('next-intl', () => ({
  useTranslations: jest.fn(() => (key: string) => key),
}))

describe('认证错误处理', () => {
  beforeEach(() => {
    jest.clearAllMocks()
  })

  describe('OAuth 错误处理', () => {
    it('应该处理用户拒绝授权错误', () => {
      const error = 'access_denied'
      const errorDescription = 'The user denied the request'

      // 模拟错误处理函数
      const handleOAuthError = (error: string, description?: string) => {
        switch (error) {
          case 'access_denied':
            return {
              type: 'user_cancelled',
              message: '用户取消了登录授权',
              userFriendly: true,
              retryable: true,
            }
          case 'invalid_client':
            return {
              type: 'config_error',
              message: '客户端配置错误，请联系管理员',
              userFriendly: true,
              retryable: false,
            }
          case 'server_error':
            return {
              type: 'server_error',
              message: '服务器暂时不可用，请稍后重试',
              userFriendly: true,
              retryable: true,
            }
          default:
            return {
              type: 'unknown_error',
              message: '登录过程中发生未知错误',
              userFriendly: true,
              retryable: true,
            }
        }
      }

      const result = handleOAuthError(error, errorDescription)

      expect(result.type).toBe('user_cancelled')
      expect(result.message).toBe('用户取消了登录授权')
      expect(result.userFriendly).toBe(true)
      expect(result.retryable).toBe(true)
    })

    it('应该处理无效客户端配置错误', () => {
      const error = 'invalid_client'
      const errorDescription = 'Invalid client credentials'

      const handleOAuthError = (error: string, description?: string) => {
        switch (error) {
          case 'invalid_client':
            return {
              type: 'config_error',
              message: '客户端配置错误，请联系管理员',
              userFriendly: true,
              retryable: false,
              details: description,
            }
          default:
            return {
              type: 'unknown_error',
              message: '登录过程中发生未知错误',
              userFriendly: true,
              retryable: true,
            }
        }
      }

      const result = handleOAuthError(error, errorDescription)

      expect(result.type).toBe('config_error')
      expect(result.message).toBe('客户端配置错误，请联系管理员')
      expect(result.retryable).toBe(false)
      expect(result.details).toBe(errorDescription)
    })

    it('应该处理服务器错误', () => {
      const error = 'server_error'
      const errorDescription = 'Internal server error'

      const handleOAuthError = (error: string, description?: string) => {
        switch (error) {
          case 'server_error':
          case 'temporarily_unavailable':
            return {
              type: 'server_error',
              message: '服务器暂时不可用，请稍后重试',
              userFriendly: true,
              retryable: true,
              retryDelay: 5000,
            }
          default:
            return {
              type: 'unknown_error',
              message: '登录过程中发生未知错误',
              userFriendly: true,
              retryable: true,
            }
        }
      }

      const result = handleOAuthError(error, errorDescription)

      expect(result.type).toBe('server_error')
      expect(result.retryable).toBe(true)
      expect(result.retryDelay).toBe(5000)
    })
  })

  describe('网络错误处理', () => {
    it('应该处理网络连接超时', () => {
      const networkError = new Error('Network request timed out')
      networkError.name = 'TimeoutError'

      // 模拟网络错误处理函数
      const handleNetworkError = (error: Error) => {
        if (
          error.name === 'TimeoutError' ||
          error.message.includes('timeout')
        ) {
          return {
            type: 'timeout_error',
            message: '网络连接超时，请检查网络连接后重试',
            userFriendly: true,
            retryable: true,
            retryDelay: 3000,
          }
        }

        if (
          error.message.includes('Network') ||
          error.message.includes('fetch')
        ) {
          return {
            type: 'network_error',
            message: '网络连接失败，请检查网络连接',
            userFriendly: true,
            retryable: true,
            retryDelay: 2000,
          }
        }

        return {
          type: 'unknown_error',
          message: '发生未知网络错误',
          userFriendly: false,
          retryable: false,
        }
      }

      const result = handleNetworkError(networkError)

      expect(result.type).toBe('timeout_error')
      expect(result.message).toBe('网络连接超时，请检查网络连接后重试')
      expect(result.retryable).toBe(true)
      expect(result.retryDelay).toBe(3000)
    })

    it('应该处理网络连接失败', () => {
      const networkError = new Error('Failed to fetch')

      const handleNetworkError = (error: Error) => {
        if (
          error.message.includes('fetch') ||
          error.message.includes('Network')
        ) {
          return {
            type: 'network_error',
            message: '网络连接失败，请检查网络连接',
            userFriendly: true,
            retryable: true,
            retryDelay: 2000,
          }
        }

        return {
          type: 'unknown_error',
          message: '发生未知网络错误',
          userFriendly: false,
          retryable: false,
        }
      }

      const result = handleNetworkError(networkError)

      expect(result.type).toBe('network_error')
      expect(result.retryable).toBe(true)
      expect(result.retryDelay).toBe(2000)
    })
  })

  describe('后端 API 错误处理', () => {
    it('应该处理后端服务不可用', () => {
      const apiError = {
        status: 503,
        message: 'Service Unavailable',
        code: 'SERVICE_UNAVAILABLE',
      }

      // 模拟 API 错误处理函数
      const handleApiError = (error: any) => {
        switch (error.status) {
          case 400:
            return {
              type: 'validation_error',
              message: '请求参数错误',
              userFriendly: true,
              retryable: false,
            }
          case 401:
            return {
              type: 'auth_error',
              message: '认证失败，请重新登录',
              userFriendly: true,
              retryable: true,
            }
          case 403:
            return {
              type: 'permission_error',
              message: '没有权限执行此操作',
              userFriendly: true,
              retryable: false,
            }
          case 500:
          case 502:
          case 503:
          case 504:
            return {
              type: 'server_error',
              message: '服务器暂时不可用，请稍后重试',
              userFriendly: true,
              retryable: true,
              retryDelay: 5000,
            }
          default:
            return {
              type: 'api_error',
              message: '服务请求失败',
              userFriendly: true,
              retryable: true,
            }
        }
      }

      const result = handleApiError(apiError)

      expect(result.type).toBe('server_error')
      expect(result.message).toBe('服务器暂时不可用，请稍后重试')
      expect(result.retryable).toBe(true)
      expect(result.retryDelay).toBe(5000)
    })

    it('应该处理认证失败错误', () => {
      const apiError = {
        status: 401,
        message: 'Unauthorized',
        code: 'AUTH_FAILED',
      }

      const handleApiError = (error: any) => {
        switch (error.status) {
          case 401:
            return {
              type: 'auth_error',
              message: '认证失败，请重新登录',
              userFriendly: true,
              retryable: true,
              action: 'redirect_to_login',
            }
          default:
            return {
              type: 'api_error',
              message: '服务请求失败',
              userFriendly: true,
              retryable: true,
            }
        }
      }

      const result = handleApiError(apiError)

      expect(result.type).toBe('auth_error')
      expect(result.action).toBe('redirect_to_login')
    })
  })

  describe('错误恢复策略', () => {
    it('应该实现指数退避重试', async () => {
      let attemptCount = 0
      const maxRetries = 3
      const baseDelay = 1000

      // 模拟会失败的操作
      const failingOperation = jest.fn().mockImplementation(() => {
        attemptCount++
        if (attemptCount < 3) {
          throw new Error('Operation failed')
        }
        return 'success'
      })

      // 模拟指数退避重试函数
      const retryWithExponentialBackoff = async (
        operation: () => Promise<any>,
        maxRetries: number,
        baseDelay: number
      ) => {
        for (let attempt = 1; attempt <= maxRetries; attempt++) {
          try {
            return await operation()
          } catch (error) {
            if (attempt === maxRetries) {
              throw error
            }

            const delay = baseDelay * Math.pow(2, attempt - 1)
            await new Promise(resolve => setTimeout(resolve, delay))
          }
        }
      }

      const result = await retryWithExponentialBackoff(
        failingOperation,
        maxRetries,
        baseDelay
      )

      expect(result).toBe('success')
      expect(failingOperation).toHaveBeenCalledTimes(3)
    })

    it('应该实现断路器模式', () => {
      // 模拟断路器状态
      let circuitState = 'CLOSED' // CLOSED, OPEN, HALF_OPEN
      let failureCount = 0
      let lastFailureTime = 0
      const failureThreshold = 5
      const timeout = 60000 // 1分钟

      // 模拟断路器函数
      const circuitBreaker = (operation: () => any) => {
        const now = Date.now()

        // 如果断路器打开且超时时间未到
        if (circuitState === 'OPEN' && now - lastFailureTime < timeout) {
          throw new Error('Circuit breaker is OPEN')
        }

        // 如果断路器打开但超时时间已到，切换到半开状态
        if (circuitState === 'OPEN' && now - lastFailureTime >= timeout) {
          circuitState = 'HALF_OPEN'
        }

        try {
          const result = operation()

          // 操作成功，重置失败计数
          if (circuitState === 'HALF_OPEN') {
            circuitState = 'CLOSED'
            failureCount = 0
          }

          return result
        } catch (error) {
          failureCount++
          lastFailureTime = now

          // 如果失败次数达到阈值，打开断路器
          if (failureCount >= failureThreshold) {
            circuitState = 'OPEN'
          }

          throw error
        }
      }

      // 测试断路器关闭状态
      expect(() => circuitBreaker(() => 'success')).not.toThrow()

      // 模拟多次失败
      for (let i = 0; i < failureThreshold; i++) {
        try {
          circuitBreaker(() => {
            throw new Error('Operation failed')
          })
        } catch (error) {
          // 预期的错误
        }
      }

      // 断路器应该已经打开
      expect(() => circuitBreaker(() => 'success')).toThrow(
        'Circuit breaker is OPEN'
      )
    })
  })

  describe('用户友好的错误消息', () => {
    it('应该根据语言环境返回本地化错误消息', () => {
      const errors = {
        access_denied: {
          en: 'Access denied by user',
          zh: '用户拒绝了访问请求',
          fr: "Accès refusé par l'utilisateur",
          de: 'Zugriff vom Benutzer verweigert',
        },
        network_error: {
          en: 'Network connection failed',
          zh: '网络连接失败',
          fr: 'Échec de la connexion réseau',
          de: 'Netzwerkverbindung fehlgeschlagen',
        },
      }

      // 模拟本地化错误消息函数
      const getLocalizedErrorMessage = (
        errorCode: string,
        locale: string = 'zh'
      ) => {
        const errorMessages = errors[errorCode as keyof typeof errors]
        if (!errorMessages) {
          return (
            errors['network_error'][
              locale as keyof (typeof errors)['network_error']
            ] || 'Unknown error'
          )
        }
        return (
          errorMessages[locale as keyof typeof errorMessages] ||
          errorMessages['en']
        )
      }

      expect(getLocalizedErrorMessage('access_denied', 'zh')).toBe(
        '用户拒绝了访问请求'
      )
      expect(getLocalizedErrorMessage('access_denied', 'en')).toBe(
        'Access denied by user'
      )
      expect(getLocalizedErrorMessage('access_denied', 'fr')).toBe(
        "Accès refusé par l'utilisateur"
      )
      expect(getLocalizedErrorMessage('network_error', 'de')).toBe(
        'Netzwerkverbindung fehlgeschlagen'
      )
    })

    it('应该提供错误恢复建议', () => {
      const errorRecoveryActions = {
        network_error: ['检查网络连接', '尝试刷新页面', '稍后重试'],
        access_denied: ['重新尝试登录', '检查账户权限', '联系管理员'],
        server_error: ['稍后重试', '检查服务状态', '联系技术支持'],
      }

      // 模拟错误恢复建议函数
      const getRecoveryActions = (errorType: string) => {
        return (
          errorRecoveryActions[
            errorType as keyof typeof errorRecoveryActions
          ] || ['刷新页面重试', '联系技术支持']
        )
      }

      const networkActions = getRecoveryActions('network_error')
      expect(networkActions).toContain('检查网络连接')
      expect(networkActions).toContain('尝试刷新页面')

      const accessActions = getRecoveryActions('access_denied')
      expect(accessActions).toContain('重新尝试登录')
      expect(accessActions).toContain('检查账户权限')
    })
  })
})
